Workbook

Sheet 总览
A1: 《余响：牵挂》立绘对白匹配总览 | B1: 《余响：牵挂》立绘对白匹配总览 | C1: 《余响：牵挂》立绘对白匹配总览 | D1: 《余响：牵挂》立绘对白匹配总览 | E1: 《余响：牵挂》立绘对白匹配总览 | F1: 《余响：牵挂》立绘对白匹配总览 | G1: 《余响：牵挂》立绘对白匹配总览 | H1: 《余响：牵挂》立绘对白匹配总览
A2: 仓库：Shellingfordh/echoes-of-us · main ｜ 生成日期：2026-08-28 ｜ 对白口径：剧情对白表 v3.7 | B2: 仓库：Shellingfordh/echoes-of-us · main ｜ 生成日期：2026-08-28 ｜ 对白口径：剧情对白表 v3.7 | C2: 仓库：Shellingfordh/echoes-of-us · main ｜ 生成日期：2026-08-28 ｜ 对白口径：剧情对白表 v3.7 | D2: 仓库：Shellingfordh/echoes-of-us · main ｜ 生成日期：2026-08-28 ｜ 对白口径：剧情对白表 v3.7 | E2: 仓库：Shellingfordh/echoes-of-us · main ｜ 生成日期：2026-08-28 ｜ 对白口径：剧情对白表 v3.7 | F2: 仓库：Shellingfordh/echoes-of-us · main ｜ 生成日期：2026-08-28 ｜ 对白口径：剧情对白表 v3.7 | G2: 仓库：Shellingfordh/echoes-of-us · main ｜ 生成日期：2026-08-28 ｜ 对白口径：剧情对白表 v3.7 | H2: 仓库：Shellingfordh/echoes-of-us · main ｜ 生成日期：2026-08-28 ｜ 对白口径：剧情对白表 v3.7
A4: 对白条目 | B4: 对白条目 | C4: 立绘文件 | D4: 立绘文件 | E4: 已绑定对白 | F4: 已绑定对白 | G4: 未绑定对白 | H4: 未绑定对白
A5: =COUNTA(对白匹配!B6:B83) -> 78 | C5: =COUNTA(资产清单!A6:A35) -> 30 | E5: =COUNTIF(对白匹配!N6:N83,"已绑定（直接）")+COUNTIF(对白匹配!N6:N83,"已绑定（近似）") -> 77 | G5: =COUNTIF(对白匹配!N6:N83,"缺少角色立绘") -> 1
A8: 关键结论 | B8: 关键结论 | C8: 关键结论 | D8: 关键结论 | E8: 关键结论 | F8: 关键结论 | G8: 关键结论 | H8: 关键结论
A9: 更新项 | B9: 当前结果 | C9: 影响 | D9: 后续建议
A10: 资产补齐 | B10: assets 已增至 30 个文件 | C10: 77/78 条对白完成角色立绘绑定 | D10: D061 仍需“高中姑娘”立绘
A11: 近似匹配 | B11: 5 条对白使用最接近表情 | C11: 可进入联调，但需美术复核 | D11: 重点复核 D003、D021、D024、D025、D056
A12: 资产去重 | B12: 检测到 2 个同 SHA 重复命名文件 | C12: 不影响路径绑定，但增加维护成本 | D12: 确认含义后保留一个规范文件名
A14: 章节对白数量 | B14: 章节对白数量 | C14: 章节对白数量 | D14: 章节对白数量 | E14: 章节对白数量 | F14: 章节对白数量 | G14: 章节对白数量 | H14: 章节对白数量
A15: 章节 | B15: 对白数 | D15: 角色版本 | E15: 对白数
A16: 第一章｜离家 | B16: =COUNTIF(对白匹配!C$6:C$83,A16) -> 25 | D16: 余念（23岁） | E16: =COUNTIF(对白匹配!J$6:J$83,D16) -> 34
A17: 第二章｜第一次放手 | B17: =COUNTIF(对白匹配!C$6:C$83,A17) -> 14 | D17: 余念（7岁） | E17: =COUNTIF(对白匹配!J$6:J$83,D17) -> 7
A18: 第三章｜一起走一段 | B18: =COUNTIF(对白匹配!C$6:C$83,A18) -> 18 | D18: 余秀兰（48岁） | E18: =COUNTIF(对白匹配!J$6:J$83,D18) -> 29
A19: 第四章｜线的尽头 | B19: =COUNTIF(对白匹配!C$6:C$83,A19) -> 8 | D19: 余秀兰（33岁） | E19: =COUNTIF(对白匹配!J$6:J$83,D19) -> 7
A20: 结局对白 | B20: =COUNTIF(对白匹配!C$6:C$83,A20) -> 13 | D20: 高中姑娘 | E20: =COUNTIF(对白匹配!J$6:J$83,D20) -> 1
A22: 使用说明 | B22: 使用说明 | C22: 使用说明 | D22: 使用说明 | E22: 使用说明 | F22: 使用说明 | G22: 使用说明 | H22: 使用说明
A23: 1. 在“对白匹配”筛选“已绑定（近似）”，优先复核 5 条近似情绪。
A24: 2. D061“高中姑娘”是当前唯一未绑定对白；补图后填写资产路径并改为“已绑定（直接）”。
A25: 3. 程序侧可将“现有资产/参考”直接作为资源路径，并保留“推荐立绘槽位”作为稳定 portrait_id。

Sheet 对白匹配
A1: 《余响：牵挂》立绘—对白匹配表 | B1: 《余响：牵挂》立绘—对白匹配表 | C1: 《余响：牵挂》立绘—对白匹配表 | D1: 《余响：牵挂》立绘—对白匹配表 | E1: 《余响：牵挂》立绘—对白匹配表 | F1: 《余响：牵挂》立绘—对白匹配表 | G1: 《余响：牵挂》立绘—对白匹配表 | H1: 《余响：牵挂》立绘—对白匹配表 | I1: 《余响：牵挂》立绘—对白匹配表 | J1: 《余响：牵挂》立绘—对白匹配表 | K1: 《余响：牵挂》立绘—对白匹配表 | L1: 《余响：牵挂》立绘—对白匹配表 | M1: 《余响：牵挂》立绘—对白匹配表 | N1: 《余响：牵挂》立绘—对白匹配表 | O1: 《余响：牵挂》立绘—对白匹配表 | P1: 《余响：牵挂》立绘—对白匹配表
A2: 口径：对白取 docs/narrative/03_剧情对白表.md（v3.7，78 条 D-ID）；按角色、年龄与情绪将 assets 中的正式立绘绑定到对白。近似匹配已单独标注，便于美术复核。 | B2: 口径：对白取 docs/narrative/03_剧情对白表.md（v3.7，78 条 D-ID）；按角色、年龄与情绪将 assets 中的正式立绘绑定到对白。近似匹配已单独标注，便于美术复核。 | C2: 口径：对白取 docs/narrative/03_剧情对白表.md（v3.7，78 条 D-ID）；按角色、年龄与情绪将 assets 中的正式立绘绑定到对白。近似匹配已单独标注，便于美术复核。 | D2: 口径：对白取 docs/narrative/03_剧情对白表.md（v3.7，78 条 D-ID）；按角色、年龄与情绪将 assets 中的正式立绘绑定到对白。近似匹配已单独标注，便于美术复核。 | E2: 口径：对白取 docs/narrative/03_剧情对白表.md（v3.7，78 条 D-ID）；按角色、年龄与情绪将 assets 中的正式立绘绑定到对白。近似匹配已单独标注，便于美术复核。 | F2: 口径：对白取 docs/narrative/03_剧情对白表.md（v3.7，78 条 D-ID）；按角色、年龄与情绪将 assets 中的正式立绘绑定到对白。近似匹配已单独标注，便于美术复核。 | G2: 口径：对白取 docs/narrative/03_剧情对白表.md（v3.7，78 条 D-ID）；按角色、年龄与情绪将 assets 中的正式立绘绑定到对白。近似匹配已单独标注，便于美术复核。 | H2: 口径：对白取 docs/narrative/03_剧情对白表.md（v3.7，78 条 D-ID）；按角色、年龄与情绪将 assets 中的正式立绘绑定到对白。近似匹配已单独标注，便于美术复核。 | I2: 口径：对白取 docs/narrative/03_剧情对白表.md（v3.7，78 条 D-ID）；按角色、年龄与情绪将 assets 中的正式立绘绑定到对白。近似匹配已单独标注，便于美术复核。 | J2: 口径：对白取 docs/narrative/03_剧情对白表.md（v3.7，78 条 D-ID）；按角色、年龄与情绪将 assets 中的正式立绘绑定到对白。近似匹配已单独标注，便于美术复核。 | K2: 口径：对白取 docs/narrative/03_剧情对白表.md（v3.7，78 条 D-ID）；按角色、年龄与情绪将 assets 中的正式立绘绑定到对白。近似匹配已单独标注，便于美术复核。 | L2: 口径：对白取 docs/narrative/03_剧情对白表.md（v3.7，78 条 D-ID）；按角色、年龄与情绪将 assets 中的正式立绘绑定到对白。近似匹配已单独标注，便于美术复核。 | M2: 口径：对白取 docs/narrative/03_剧情对白表.md（v3.7，78 条 D-ID）；按角色、年龄与情绪将 assets 中的正式立绘绑定到对白。近似匹配已单独标注，便于美术复核。 | N2: 口径：对白取 docs/narrative/03_剧情对白表.md（v3.7，78 条 D-ID）；按角色、年龄与情绪将 assets 中的正式立绘绑定到对白。近似匹配已单独标注，便于美术复核。 | O2: 口径：对白取 docs/narrative/03_剧情对白表.md（v3.7，78 条 D-ID）；按角色、年龄与情绪将 assets 中的正式立绘绑定到对白。近似匹配已单独标注，便于美术复核。 | P2: 口径：对白取 docs/narrative/03_剧情对白表.md（v3.7，78 条 D-ID）；按角色、年龄与情绪将 assets 中的正式立绘绑定到对白。近似匹配已单独标注，便于美术复核。
A3: 资产更新：main/assets 已有 30 个文件；77 条对白已绑定，D061“高中姑娘”仍缺角色立绘。 | B3: 资产更新：main/assets 已有 30 个文件；77 条对白已绑定，D061“高中姑娘”仍缺角色立绘。 | C3: 资产更新：main/assets 已有 30 个文件；77 条对白已绑定，D061“高中姑娘”仍缺角色立绘。 | D3: 资产更新：main/assets 已有 30 个文件；77 条对白已绑定，D061“高中姑娘”仍缺角色立绘。 | E3: 资产更新：main/assets 已有 30 个文件；77 条对白已绑定，D061“高中姑娘”仍缺角色立绘。 | F3: 资产更新：main/assets 已有 30 个文件；77 条对白已绑定，D061“高中姑娘”仍缺角色立绘。 | G3: 资产更新：main/assets 已有 30 个文件；77 条对白已绑定，D061“高中姑娘”仍缺角色立绘。 | H3: 资产更新：main/assets 已有 30 个文件；77 条对白已绑定，D061“高中姑娘”仍缺角色立绘。 | I3: 资产更新：main/assets 已有 30 个文件；77 条对白已绑定，D061“高中姑娘”仍缺角色立绘。 | J3: 资产更新：main/assets 已有 30 个文件；77 条对白已绑定，D061“高中姑娘”仍缺角色立绘。 | K3: 资产更新：main/assets 已有 30 个文件；77 条对白已绑定，D061“高中姑娘”仍缺角色立绘。 | L3: 资产更新：main/assets 已有 30 个文件；77 条对白已绑定，D061“高中姑娘”仍缺角色立绘。 | M3: 资产更新：main/assets 已有 30 个文件；77 条对白已绑定，D061“高中姑娘”仍缺角色立绘。 | N3: 资产更新：main/assets 已有 30 个文件；77 条对白已绑定，D061“高中姑娘”仍缺角色立绘。 | O3: 资产更新：main/assets 已有 30 个文件；77 条对白已绑定，D061“高中姑娘”仍缺角色立绘。 | P3: 资产更新：main/assets 已有 30 个文件；77 条对白已绑定，D061“高中姑娘”仍缺角色立绘。
A5: 序号 | B5: 对白ID | C5: 章节 | D5: 场景 | E5: 触发条件 | F5: 角色 | G5: 台词 | H5: 原情绪 | I5: 阻塞 | J5: 角色版本 | K5: 情绪组 | L5: 推荐立绘槽位 | M5: 现有资产/参考 | N5: 匹配状态 | O5: 备注 | P5: 对白来源
A6: 1 | B6: D001 | C6: 第一章｜离家 | D6: Scene 01｜搬家早晨与房间探索 | E6: 首次调查封好的纸箱；O001 后触发 | F6: 余念·独白 | G6: “终于收完了！我还以为真要收出十箱八箱呢。……也好，东西少，走起来省事。” | H6: 松快；用效率判断压住一点空落 | I6: 否 | J6: 余念（23岁） | K6: 受伤/低落 | L6: YN23_SAD | M6: assets/余念（23）：强忍悲戚.png | N6: 已绑定（直接） | O6: 角色、年龄与情绪方向一致。 | P6: https://github.com/Shellingfordh/echoes-of-us/blob/main/docs/narrative/03_%E5%89%A7%E6%83%85%E5%AF%B9%E7%99%BD%E8%A1%A8.md
A7: 2 | B7: D002 | C7: 第一章｜离家 | D7: Scene 01｜搬家早晨与房间探索 | E7: 首次调查敞开的行李箱；O002 后触发 | F7: 余念·独白 | G7: “我就知道，她到底什么时候进来的……每次都这样，也不先问我一声。算了，药先放着吧。” | H7: 熟悉、烦；明确介意“没问我”，但不拒绝所有照料 | I7: 否 | J7: 余念（23岁） | K7: 烦躁/防御 | L7: YN23_IRRITATED | M7: assets/余念（23）：烦躁郁闷.png | N7: 已绑定（直接） | O7: 角色、年龄与情绪方向一致。 | P7: https://github.com/Shellingfordh/echoes-of-us/blob/main/docs/narrative/03_%E5%89%A7%E6%83%85%E5%AF%B9%E7%99%BD%E8%A1%A8.md
A8: 3 | B8: D003 | C8: 第一章｜离家 | D8: Scene 01｜搬家早晨与房间探索 | E8: 首次调查书桌；O003 后触发 | F8: 余念·独白 | G8: “总算等到这一天了。……怎么还真有点紧张……没事，到了再说！” | H8: 期待、紧张；自己把情绪压回实际行动 | I8: 否 | J8: 余念（23岁） | K8: 恐惧/紧张 | L8: YN23_FEAR | M8: assets/余念（23）：正常状态.png | N8: 已绑定（近似） | O8: 角色与年龄一致；紧张程度较轻，暂用正常状态，建议美术复核。 | P8: https://github.com/Shellingfordh/echoes-of-us/blob/main/docs/narrative/03_%E5%89%A7%E6%83%85%E5%AF%B9%E7%99%BD%E8%A1%A8.md
A9: 4 | B9: D004 | C9: 第一章｜离家 | D9: Scene 01｜搬家早晨与房间探索 | E9: 窗玻璃处第一次进入定点观察；O004 后触发 | F9: 余念·独白 | G9: “看着还行嘛。至少不像第一次出远门的人。” | H9: 轻松里有一点虚；确认自己是否显得准备充分 | I9: 否 | J9: 余念（23岁） | K9: 温暖/轻快 | L9: YN23_WARM | M9: assets/余念（23）：欣然愉悦.png | N9: 已绑定（直接） | O9: 角色、年龄与情绪方向一致。 | P9: https://github.com/Shellingfordh/echoes-of-us/blob/main/docs/narrative/03_%E5%89%A7%E6%83%85%E5%AF%B9%E7%99%BD%E8%A1%A8.md
A10: 5 | B10: D041 | C10: 第一章｜离家 | D10: Scene 01｜搬家早晨与房间探索 | E10: 钻入床底调查耳机；O041 后触发 | F10: 余念·独白 | G10: “我就说没丢嘛。妈前两天还让我别找了，再买一副。幸好没听她的。……这种地方也就我进得来，要换成她，腰肯定不行。” | H10: 得意、生活化；相信自己的判断和行动能力 | I10: 否 | J10: 余念（23岁） | K10: 温暖/轻快 | L10: YN23_WARM | M10: assets/余念（23）：欣然愉悦.png | N10: 已绑定（直接） | O10: 角色、年龄与情绪方向一致。 | P10: https://github.com/Shellingfordh/echoes-of-us/blob/main/docs/narrative/03_%E5%89%A7%E6%83%85%E5%AF%B9%E7%99%BD%E8%A1%A8.md
A11: 6 | B11: D042 | C11: 第一章｜离家 | D11: Scene 01｜搬家早晨与房间探索 | E11: 跳上柜顶调查相框；O042 后触发 | F11: 余念·独白 | G11: “妈以前头发这么长啊。……她现在拍照还老说自己不上镜，明明这张倒笑得挺开心的。” | H11: 随口、轻微柔软；评价照片里的年轻母亲 | I11: 否 | J11: 余念（23岁） | K11: 温暖/轻快 | L11: YN23_WARM | M11: assets/余念（23）：欣然愉悦.png | N11: 已绑定（直接） | O11: 角色、年龄与情绪方向一致。 | P11: https://github.com/Shellingfordh/echoes-of-us/blob/main/docs/narrative/03_%E5%89%A7%E6%83%85%E5%AF%B9%E7%99%BD%E8%A1%A8.md
A12: 7 | B12: D043 | C12: 第一章｜离家 | D12: Scene 01｜搬家早晨与房间探索 | E12: 调查衣柜中的男式外套；O043 后触发 | F12: 余念·独白 | G12: “爸爸的衣服……还留着。每次收拾都说‘下回再弄’，下回又原样挂回去。……算了，她想留就留吧。” | H12: 熟悉、回避；评价母亲保留旧物的习惯 | I12: 否 | J12: 余念（23岁） | K12: 受伤/低落 | L12: YN23_SAD | M12: assets/余念（23）：强忍悲戚.png | N12: 已绑定（直接） | O12: 角色、年龄与情绪方向一致。 | P12: https://github.com/Shellingfordh/echoes-of-us/blob/main/docs/narrative/03_%E5%89%A7%E6%83%85%E5%AF%B9%E7%99%BD%E8%A1%A8.md
A13: 8 | B13: D044 | C13: 第一章｜离家 | D13: Scene 01｜搬家早晨与房间探索 | E13: 窗前抬腕看见旧串珠；O044 后触发 | F13: 余念·独白 | G13: “这东西居然还没散架。不过，换根线，应该也还能戴。” | H13: 自然；珍惜而不自知 | I13: 否 | J13: 余念（23岁） | K13: 温暖/轻快 | L13: YN23_WARM | M13: assets/余念（23）：欣然愉悦.png | N13: 已绑定（直接） | O13: 角色、年龄与情绪方向一致。 | P13: https://github.com/Shellingfordh/echoes-of-us/blob/main/docs/narrative/03_%E5%89%A7%E6%83%85%E5%AF%B9%E7%99%BD%E8%A1%A8.md
A14: 9 | B14: D005 | C14: 第一章｜离家 | D14: Scene 02｜黄色旧雨伞 | E14: 完成必要探索后，余秀兰拿黄伞进入房间 | F14: 余秀兰 | G14: “雨伞没拿，来，给你装上。你这拉链怎么又卡了？” | H14: 自然、忙碌；进门先做事 | I14: 是 | J14: 余秀兰（48岁） | K14: 温暖/轻快 | L14: YXL48_WARM | M14: assets/余秀兰（48）：欣然愉悦.png | N14: 已绑定（直接） | O14: 角色、年龄与情绪方向一致。 | P14: https://github.com/Shellingfordh/echoes-of-us/blob/main/docs/narrative/03_%E5%89%A7%E6%83%85%E5%AF%B9%E7%99%BD%E8%A1%A8.md
A15: 10 | B15: D006 | C15: 第一章｜离家 | D15: Scene 02｜黄色旧雨伞 | E15: 余秀兰把黄伞往行李箱里塞 | F15: 余秀兰 | G15: “那边这两天有雨。塞着吧，省得到地方现买。” | H15: 关心、习惯性安排 | I15: 是 | J15: 余秀兰（48岁） | K15: 关切/专注 | L15: YXL48_CONCERNED | M15: assets/余秀兰（48）：满眼宠溺.png | N15: 已绑定（直接） | O15: 角色、年龄与情绪方向一致。 | P15: https://github.com/Shellingfordh/echoes-of-us/blob/main/docs/narrative/03_%E5%89%A7%E6%83%85%E5%AF%B9%E7%99%BD%E8%A1%A8.md
A16: 11 | B16: D007 | C16: 第一章｜离家 | D16: Scene 02｜黄色旧雨伞 | E16: 余念伸手阻止 | F16: 余念 | G16: “妈，真塞不下了，你别硬塞啊。” | H16: 克制、略急 | I16: 是 | J16: 余念（23岁） | K16: 烦躁/防御 | L16: YN23_IRRITATED | M16: assets/余念（23）：烦躁郁闷.png | N16: 已绑定（直接） | O16: 角色、年龄与情绪方向一致。 | P16: https://github.com/Shellingfordh/echoes-of-us/blob/main/docs/narrative/03_%E5%89%A7%E6%83%85%E5%AF%B9%E7%99%BD%E8%A1%A8.md
A17: 12 | B17: D008 | C17: 第一章｜离家 | D17: Scene 02｜黄色旧雨伞 | E17: 余念把伞往外抽 | F17: 余念 | G17: “到那儿再买就行，便利店多的是。” | H17: 用解决方案维护边界 | I17: 是 | J17: 余念（23岁） | K17: 中性/克制 | L17: YN23_NEUTRAL | M17: assets/余念（23）：正常状态.png | N17: 已绑定（直接） | O17: 角色、年龄与情绪方向一致。 | P17: https://github.com/Shellingfordh/echoes-of-us/blob/main/docs/narrative/03_%E5%89%A7%E6%83%85%E5%AF%B9%E7%99%BD%E8%A1%A8.md
... A29: 24 | B29: D018 | C29: 第一章｜离家 | D29: Scene 03｜显线、回弹与试探 | E29: 再次尝试离开仍失败，线重新绷紧；黄伞与线开始共鸣 | F29: 余念 | G29: “……妈妈不想让我走？” | H29: 委屈、抗拒；错误理解正式成立 | I29: 是 | J29: 余念（23岁） | K29: 受伤/低落 | L29: YN23_SAD | M29: assets/余念（23）：强忍悲戚.png | N29: 已绑定（直接） | O29: 角色、年龄与情绪方向一致。 | P29: https://github.com/Shellingfordh/echoes-of-us/blob/main/docs/narrative/03_%E5%89%A7%E6%83%85%E5%AF%B9%E7%99%BD%E8%A1%A8.md
A30: 25 | B30: D047 | C30: 第一章｜离家 | D30: Scene 03｜显线、回弹与试探 | E30: 显线后调查任意普通线状物；O047 后触发一次 | F30: 余念·独白 | H30: 不安、烦躁、抗拒；不做主题总结 | I30: 否 | J30: 余念（23岁） | K30: 烦躁/防御 | L30: YN23_IRRITATED | M30: assets/余念（23）：烦躁郁闷.png | N30: 已绑定（直接） | O30: 角色、年龄与情绪方向一致。 | P30: https://github.com/Shellingfordh/echoes-of-us/blob/main/docs/narrative/03_%E5%89%A7%E6%83%85%E5%AF%B9%E7%99%BD%E8%A1%A8.md
A31: 26 | B31: D019 | C31: 第二章｜第一次放手 | D31: Scene 04｜童年与母亲的位置 | E31: 黄伞触发 2009 年秋回放，七岁余念向前跑 | F31: 七岁余念 | G31: “妈妈你快点！我先走啦！” | H31: 兴奋、迫不及待 | I31: 否 | J31: 余念（7岁） | K31: 温暖/轻快 | L31: YN07_WARM | M31: assets/余念（7）：欣然愉悦.png | N31: 已绑定（直接） | O31: 角色、年龄与情绪方向一致。 | P31: https://github.com/Shellingfordh/echoes-of-us/blob/main/docs/narrative/03_%E5%89%A7%E6%83%85%E5%AF%B9%E7%99%BD%E8%A1%A8.md
A32: 27 | B32: D020 | C32: 第二章｜第一次放手 | D32: Scene 04｜童年与母亲的位置 | E32: 玩家第一次从年轻余秀兰一端看见牵挂线 | F32: 年轻余秀兰 | G32: “慢点儿。看路。” | H32: 普通母亲式提醒 | I32: 否 | J32: 余秀兰（33岁） | K32: 中性/克制 | L32: YXL33_NEUTRAL | M32: assets/余秀兰（33）：正常状态.png | N32: 已绑定（直接） | O32: 角色、年龄与情绪方向一致。 | P32: https://github.com/Shellingfordh/echoes-of-us/blob/main/docs/narrative/03_%E5%89%A7%E6%83%85%E5%AF%B9%E7%99%BD%E8%A1%A8.md
A33: 28 | B33: D021 | C33: 第二章｜第一次放手 | D33: Scene 04｜童年与母亲的位置 | E33: 孩子接近危险或木板将失稳 | F33: 年轻余秀兰 | G33: “余念，停！” | H33: 本能保护、惊慌 | I33: 否 | J33: 余秀兰（33岁） | K33: 恐惧/紧张 | L33: YXL33_FEAR | M33: assets/余秀兰（33）：心脏骤停.jpg | N33: 已绑定（近似） | O33: 角色与年龄一致；当前无完全同义表情，按最接近情绪绑定，建议美术复核。 | P33: https://github.com/Shellingfordh/echoes-of-us/blob/main/docs/narrative/03_%E5%89%A7%E6%83%85%E5%AF%B9%E7%99%BD%E8%A1%A8.md
A34: 29 | B34: D022 | C34: 第二章｜第一次放手 | D34: Scene 04｜童年与母亲的位置 | E34: 孩子被张力顿住后回头 | F34: 七岁余念 | G34: “你干嘛呀，我都没碰到水！” | H34: 疑惑、小小不满；孩子只看到眼前的事 | I34: 否 | J34: 余念（7岁） | K34: 烦躁/防御 | L34: YN07_IRRITATED | M34: assets/余念（7）：积郁憋闷.png | N34: 已绑定（直接） | O34: 角色、年龄与情绪方向一致。 | P34: https://github.com/Shellingfordh/echoes-of-us/blob/main/docs/narrative/03_%E5%89%A7%E6%83%85%E5%AF%B9%E7%99%BD%E8%A1%A8.md
A35: 30 | B35: D023 | C35: 第二章｜第一次放手 | D35: Scene 04｜童年与母亲的位置 | E35: 到达成年人无法通过的窄处 | F35: 七岁余念 | G35: “这个我能钻！你别过来，我自己来。” | H35: 自信、想证明自己 | I35: 否 | J35: 余念（7岁） | K35: 中性/克制 | L35: YN07_NEUTRAL | M35: assets/余念（7）：淡然自若.png | N35: 已绑定（直接） | O35: 角色、年龄与情绪方向一致。 | P35: https://github.com/Shellingfordh/echoes-of-us/blob/main/docs/narrative/03_%E5%89%A7%E6%83%85%E5%AF%B9%E7%99%BD%E8%A1%A8.md
A36: 31 | B36: D048 | C36: 第二章｜第一次放手 | D36: Scene 04｜童年与母亲的位置 | E36: 自行车挡路，小余念试着搬 | F36: 七岁余念 | G36: “我搬得动——……搬不动。” | H36: 逞强后立刻承认 | I36: 否 | J36: 余念（7岁） | K36: 烦躁/防御 | L36: YN07_IRRITATED | M36: assets/余念（7）：积郁憋闷.png | N36: 已绑定（直接） | O36: 角色、年龄与情绪方向一致。 | P36: https://github.com/Shellingfordh/echoes-of-us/blob/main/docs/narrative/03_%E5%89%A7%E6%83%85%E5%AF%B9%E7%99%BD%E8%A1%A8.md
A37: 32 | B37: D049 | C37: 第二章｜第一次放手 | D37: Scene 04｜童年与母亲的位置 | E37: 余秀兰推开自行车 | F37: 年轻余秀兰 | G37: “让开点，别砸着脚。” | H37: 自然承担；不强调“妈妈能做” | I37: 否 | J37: 余秀兰（33岁） | K37: 温暖/轻快 | L37: YXL33_WARM | M37: assets/余秀兰（33）：含情凝望.png | N37: 已绑定（直接） | O37: 角色、年龄与情绪方向一致。 | P37: https://github.com/Shellingfordh/echoes-of-us/blob/main/docs/narrative/03_%E5%89%A7%E6%83%85%E5%AF%B9%E7%99%BD%E8%A1%A8.md
A38: 33 | B38: D050 | C38: 第二章｜第一次放手 | D38: Scene 04｜童年与母亲的位置 | E38: 水坑前孩子跑远，线开始紧 | F38: 七岁余念 | G38: “这点水我肯定能过去！” | H38: 主动、觉得自己没问题 | I38: 否 | J38: 余念（7岁） | K38: 烦躁/兴奋 | L38: YN07_NEUTRAL | M38: assets/余念（7）：欣然愉悦(透).png | N38: 已绑定（直接） | O38: 角色、年龄与情绪方向一致。 | P38: https://github.com/Shellingfordh/echoes-of-us/blob/main/assets/%E4%BD%99%E5%BF%B5%EF%BC%887%EF%BC%89%EF%BC%9A%E6%AC%A3%E7%84%B6%E6%84%89%E6%82%A6(%E9%80%8F).png
A39: 34 | B39: D051 | C39: 第二章｜第一次放手 | D39: Scene 04｜童年与母亲的位置 | E39: 余秀兰主动向前靠近，线松下来 | F39: 年轻余秀兰 | G39: “行行行，你慢点儿，我跟在后面哦。” | H39: 能够退一步，不说教 | I39: 否 | J39: 余秀兰（33岁） | K39: 中性/克制 | L39: YXL33_NEUTRAL | M39: assets/余秀兰（33）：正常状态.png | N39: 已绑定（直接） | O39: 角色、年龄与情绪方向一致。 | P39: https://github.com/Shellingfordh/echoes-of-us/blob/main/docs/narrative/03_%E5%89%A7%E6%83%85%E5%AF%B9%E7%99%BD%E8%A1%A8.md
A40: 35 | B40: D024 | C40: 第二章｜第一次放手 | D40: Scene 05｜坠落、攀线与第一次放手 | E40: 孩子坠落后被线吊住并开始沿线攀回 | F40: 年轻余秀兰 | G40: “余念！抓紧！别往下看——对，往上爬。妈妈在这儿。” | H40: 恐惧，但强迫自己镇定；句子被动作切碎 | I40: 否 | J40: 余秀兰（33岁） | K40: 恐惧/紧张 | L40: YXL33_FEAR | M40: assets/余秀兰（33）：心脏骤停.jpg | N40: 已绑定（近似） | O40: 角色与年龄一致；当前无完全同义表情，按最接近情绪绑定，建议美术复核。 | P40: https://github.com/Shellingfordh/echoes-of-us/blob/main/docs/narrative/03_%E5%89%A7%E6%83%85%E5%AF%B9%E7%99%BD%E8%A1%A8.md
A41: 36 | B41: D052 | C41: 第二章｜第一次放手 | D41: Scene 05｜坠落、攀线与第一次放手 | E41: 孩子爬回安全处 | F41: 七岁余念 | G41: “你看，妈妈，我自己上来的！” | H41: 喘着气，还要强调“自己” | I41: 否 | J41: 余念（7岁） | K41: 高兴/激动 | L41: YN07_NEUTRAL | M41: assets/余念（7）：欣然愉悦(透).png | N41: 已绑定（直接） | O41: 角色、年龄与情绪方向一致。 | P41: https://github.com/Shellingfordh/echoes-of-us/blob/main/assets/%E4%BD%99%E5%BF%B5%EF%BC%887%EF%BC%89%EF%BC%9A%E6%AC%A3%E7%84%B6%E6%84%89%E6%82%A6(%E9%80%8F).pngs/余念（7）：欣然愉悦(透).png
A42: 37 | B42: D053 | C42: 第二章｜第一次放手 | D42: Scene 05｜坠落、攀线与第一次放手 | E42: 母亲检查她确认没伤到 | F42: 年轻余秀兰 | G42: “嗯，妈妈看见了。宝宝，真棒！膝盖呢，疼不疼？” | H42: 先承认，再立刻回到照料 | I42: 否 | J42: 余秀兰（33岁） | K42: 关切/专注 | L42: YXL33_CONCERNED | M42: assets/余秀兰（33）：含情凝望.png | N42: 已绑定（直接） | O42: 角色、年龄与情绪方向一致。 | P42: https://github.com/Shellingfordh/echoes-of-us/blob/main/docs/narrative/03_%E5%89%A7%E6%83%85%E5%AF%B9%E7%99%BD%E8%A1%A8.md
... A56: 51 | B56: D031 | C56: 第三章｜一起走一段 | D56: Scene 08｜仓库与能力差异 | E56: 母亲完成重物处理 | F56: 余秀兰 | G56: “行。慢点，里面黑。” | H56: 克制、愿意等待 | I56: 否 | J56: 余秀兰（48岁） | K56: 中性/克制 | L56: YXL48_NEUTRAL | M56: assets/余秀兰（48）：正常状态.png | N56: 已绑定（直接） | O56: 角色、年龄与情绪方向一致。 | P56: https://github.com/Shellingfordh/echoes-of-us/blob/main/docs/narrative/03_%E5%89%A7%E6%83%85%E5%AF%B9%E7%99%BD%E8%A1%A8.md
A57: 52 | B57: D061 | C57: 第三章｜一起走一段 | D57: Scene 08｜仓库与能力差异 | E57: 常来帮忙的高中姑娘出现 | F57: 高中姑娘 | G57: “姨，我来我来。” | H57: 熟门熟路 | I57: 否 | J57: 高中姑娘 | K57: 中性/克制 | L57: HS_GIRL_NEUTRAL | N57: 缺少角色立绘 | O57: 当前 assets 中没有该角色立绘。 | P57: https://github.com/Shellingfordh/echoes-of-us/blob/main/docs/narrative/03_%E5%89%A7%E6%83%85%E5%AF%B9%E7%99%BD%E8%A1%A8.md
A58: 53 | B58: D062 | C58: 第三章｜一起走一段 | D58: Scene 08｜仓库与能力差异 | E58: 母亲把轻的递给她 | F58: 余秀兰 | G58: “你拿这个。那个沉，别逞能。” | H58: 对别人也使用同样的照料语言 | I58: 否 | J58: 余秀兰（48岁） | K58: 关切/专注 | L58: YXL48_CONCERNED | M58: assets/余秀兰（48）：满眼宠溺.png | N58: 已绑定（直接） | O58: 角色、年龄与情绪方向一致。 | P58: https://github.com/Shellingfordh/echoes-of-us/blob/main/docs/narrative/03_%E5%89%A7%E6%83%85%E5%AF%B9%E7%99%BD%E8%A1%A8.md
A59: 54 | B59: D032 | C59: 第三章｜一起走一段 | D59: Scene 09｜天台接力 | E59: 余秀兰在低处锚定，让余念先上 | F59: 余秀兰 | G59: “你先上。上去站稳再说。” | H59: 沉着、把主动权交出去 | I59: 否 | J59: 余秀兰（48岁） | K59: 关切/专注 | L59: YXL48_CONCERNED | M59: assets/余秀兰（48）：满眼宠溺.png | N59: 已绑定（直接） | O59: 角色、年龄与情绪方向一致。 | P59: https://github.com/Shellingfordh/echoes-of-us/blob/main/docs/narrative/03_%E5%89%A7%E6%83%85%E5%AF%B9%E7%99%BD%E8%A1%A8.md
A60: 55 | B60: D033 | C60: 第三章｜一起走一段 | D60: Scene 09｜天台接力 | E60: 余念在高处完成锚定并接母亲 | F60: 余念 | G60: “好了。你上来吧。” | H60: 信任、轻盈、平等 | I60: 否 | J60: 余念（23岁） | K60: 温暖/轻快 | L60: YN23_WARM | M60: assets/余念（23）：欣然愉悦.png | N60: 已绑定（直接） | O60: 角色、年龄与情绪方向一致。 | P60: https://github.com/Shellingfordh/echoes-of-us/blob/main/docs/narrative/03_%E5%89%A7%E6%83%85%E5%AF%B9%E7%99%BD%E8%A1%A8.md
A61: 56 | B61: D063 | C61: 第三章｜一起走一段 | D61: Scene 09｜天台接力 | E61: 母亲真正把重量交给女儿 | F61: 余秀兰 | G61: “别松啊。” | H61: 极短；信任落实在依赖上 | I61: 否 | J61: 余秀兰（48岁） | K61: 温暖/轻快 | L61: YXL48_WARM | M61: assets/余秀兰（48）：欣然愉悦.png | N61: 已绑定（直接） | O61: 角色、年龄与情绪方向一致。 | P61: https://github.com/Shellingfordh/echoes-of-us/blob/main/docs/narrative/03_%E5%89%A7%E6%83%85%E5%AF%B9%E7%99%BD%E8%A1%A8.md
A62: 57 | B62: D064 | C62: 第三章｜一起走一段 | D62: Scene 09｜天台接力 | E62: 女儿回应 | F62: 余念 | G62: “没松。” | H62: 极短；第三章情感峰值 | I62: 否 | J62: 余念（23岁） | K62: 中性/克制 | L62: YN23_NEUTRAL | M62: assets/余念（23）：正常状态.png | N62: 已绑定（直接） | O62: 角色、年龄与情绪方向一致。 | P62: https://github.com/Shellingfordh/echoes-of-us/blob/main/docs/narrative/03_%E5%89%A7%E6%83%85%E5%AF%B9%E7%99%BD%E8%A1%A8.md
A63: 58 | B63: D034 | C63: 第四章｜线的尽头 | D63: Scene 10｜检票口外：再次越界 | E63: 检票口外，余秀兰最后整理袋子 | F63: 余秀兰 | G63: “这袋路上吃，这袋到了再开。别都塞一块儿，一会儿又找不着。” | H63: 越接近真正分离越忙 | I63: 是 | J63: 余秀兰（48岁） | K63: 中性/克制 | L63: YXL48_NEUTRAL | M63: assets/余秀兰（48）：正常状态.png | N63: 已绑定（直接） | O63: 角色、年龄与情绪方向一致。 | P63: https://github.com/Shellingfordh/echoes-of-us/blob/main/docs/narrative/03_%E5%89%A7%E6%83%85%E5%AF%B9%E7%99%BD%E8%A1%A8.md
A64: 59 | B64: D035 | C64: 第四章｜线的尽头 | D64: Scene 10｜检票口外：再次越界 | E64: 余念接过袋子 | F64: 余念 | G64: “行，我知道。你给我吧。” | H64: 疲惫，但仍压着 | I64: 是 | J64: 余念（23岁） | K64: 中性/克制 | L64: YN23_NEUTRAL | M64: assets/余念（23）：正常状态.png | N64: 已绑定（直接） | O64: 角色、年龄与情绪方向一致。 | P64: https://github.com/Shellingfordh/echoes-of-us/blob/main/docs/narrative/03_%E5%89%A7%E6%83%85%E5%AF%B9%E7%99%BD%E8%A1%A8.md
A65: 60 | B65: D036 | C65: 第四章｜线的尽头 | D65: Scene 10｜检票口外：再次越界 | E65: 母亲继续确认 | F65: 余秀兰 | G65: “到地方给我打个电话。还有那个房子，我越想越不放心。” | H65: 连续确认开始升级 | I65: 是 | J65: 余秀兰（48岁） | K65: 中性/克制 | L65: YXL48_NEUTRAL | M65: assets/余秀兰（48）：正常状态.png | N65: 已绑定（直接） | O65: 角色、年龄与情绪方向一致。 | P65: https://github.com/Shellingfordh/echoes-of-us/blob/main/docs/narrative/03_%E5%89%A7%E6%83%85%E5%AF%B9%E7%99%BD%E8%A1%A8.md
...

Sheet 资产清单
A1: 立绘资产清单与目录审计 | B1: 立绘资产清单与目录审计 | C1: 立绘资产清单与目录审计 | D1: 立绘资产清单与目录审计 | E1: 立绘资产清单与目录审计 | F1: 立绘资产清单与目录审计 | G1: 立绘资产清单与目录审计 | H1: 立绘资产清单与目录审计 | I1: 立绘资产清单与目录审计 | J1: 立绘资产清单与目录审计
A2: main/assets：30 个文件 ｜ 角色立绘：29 个 ｜ 通用情绪参考：1 个 ｜ 同 SHA 重复命名：2 个 | B2: main/assets：30 个文件 ｜ 角色立绘：29 个 ｜ 通用情绪参考：1 个 ｜ 同 SHA 重复命名：2 个 | C2: main/assets：30 个文件 ｜ 角色立绘：29 个 ｜ 通用情绪参考：1 个 ｜ 同 SHA 重复命名：2 个 | D2: main/assets：30 个文件 ｜ 角色立绘：29 个 ｜ 通用情绪参考：1 个 ｜ 同 SHA 重复命名：2 个 | E2: main/assets：30 个文件 ｜ 角色立绘：29 个 ｜ 通用情绪参考：1 个 ｜ 同 SHA 重复命名：2 个 | F2: main/assets：30 个文件 ｜ 角色立绘：29 个 ｜ 通用情绪参考：1 个 ｜ 同 SHA 重复命名：2 个 | G2: main/assets：30 个文件 ｜ 角色立绘：29 个 ｜ 通用情绪参考：1 个 ｜ 同 SHA 重复命名：2 个 | H2: main/assets：30 个文件 ｜ 角色立绘：29 个 ｜ 通用情绪参考：1 个 ｜ 同 SHA 重复命名：2 个 | I2: main/assets：30 个文件 ｜ 角色立绘：29 个 ｜ 通用情绪参考：1 个 ｜ 同 SHA 重复命名：2 个 | J2: main/assets：30 个文件 ｜ 角色立绘：29 个 ｜ 通用情绪参考：1 个 ｜ 同 SHA 重复命名：2 个
A4: 仓库内已发现的图片资产 | B4: 仓库内已发现的图片资产 | C4: 仓库内已发现的图片资产 | D4: 仓库内已发现的图片资产 | E4: 仓库内已发现的图片资产 | F4: 仓库内已发现的图片资产 | G4: 仓库内已发现的图片资产 | H4: 仓库内已发现的图片资产 | I4: 仓库内已发现的图片资产 | J4: 仓库内已发现的图片资产
A5: 仓库路径 | B5: 文件名 | C5: 所在目录 | D5: 文件大小（字节） | E5: 大小（MB） | F5: 角色 | G5: 情绪 | H5: 用途判断 | I5: 重复/绑定结论 | J5: 来源URL
A6: assets/人像质感调节-情绪调节-哀悼压抑.png | B6: 人像质感调节-情绪调节-哀悼压抑.png | C6: assets | D6: 2921833 | E6: =D6/1024/1024 -> 2.7864771 | F6: 未标注 | G6: 人像质感调节-情绪调节-哀悼压抑 | H6: 通用情绪参考 | I6: 通用参考，不直接绑定 | J6: https://raw.githubusercontent.com/Shellingfordh/echoes-of-us/main/assets/人像质感调节-情绪调节-哀悼压抑.png
A7: assets/余念（23）：强忍悲戚.png | B7: 余念（23）：强忍悲戚.png | C7: assets | D7: 2845211 | E7: =D7/1024/1024 -> 2.7134047 | F7: 余念（23） | G7: 强忍悲戚 | H7: 正式角色立绘 | I7: 可用于对白绑定 | J7: https://raw.githubusercontent.com/Shellingfordh/echoes-of-us/main/assets/余念（23）：强忍悲戚.png
A8: assets/余念（23）：欣然愉悦.png | B8: 余念（23）：欣然愉悦.png | C8: assets | D8: 2867446 | E8: =D8/1024/1024 -> 2.7346096 | F8: 余念（23） | G8: 欣然愉悦 | H8: 正式角色立绘 | I8: 可用于对白绑定 | J8: https://raw.githubusercontent.com/Shellingfordh/echoes-of-us/main/assets/余念（23）：欣然愉悦.png
A9: assets/余念（23）：正常状态.png | B9: 余念（23）：正常状态.png | C9: assets | D9: 2559785 | E9: =D9/1024/1024 -> 2.4412012 | F9: 余念（23） | G9: 正常状态 | H9: 正式角色立绘 | I9: 可用于对白绑定 | J9: https://raw.githubusercontent.com/Shellingfordh/echoes-of-us/main/assets/余念（23）：正常状态.png
A10: assets/余念（23）：烦躁郁闷.png | B10: 余念（23）：烦躁郁闷.png | C10: assets | D10: 2893505 | E10: =D10/1024/1024 -> 2.7594614 | F10: 余念（23） | G10: 烦躁郁闷 | H10: 正式角色立绘 | I10: 可用于对白绑定 | J10: https://raw.githubusercontent.com/Shellingfordh/echoes-of-us/main/assets/余念（23）：烦躁郁闷.png
A11: assets/余念（23）：隐忍愠怒.png | B11: 余念（23）：隐忍愠怒.png | C11: assets | D11: 2888881 | E11: =D11/1024/1024 -> 2.7550516 | F11: 余念（23） | G11: 隐忍愠怒 | H11: 正式角色立绘 | I11: 可用于对白绑定 | J11: https://raw.githubusercontent.com/Shellingfordh/echoes-of-us/main/assets/余念（23）：隐忍愠怒.png
A12: assets/余念（23）：难以置信.png | B12: 余念（23）：难以置信.png | C12: assets | D12: 2865543 | E12: =D12/1024/1024 -> 2.7327948 | F12: 余念（23） | G12: 难以置信 | H12: 正式角色立绘 | I12: 可用于对白绑定 | J12: https://raw.githubusercontent.com/Shellingfordh/echoes-of-us/main/assets/余念（23）：难以置信.png
A13: assets/余念（7）：惊魂未定.png | B13: 余念（7）：惊魂未定.png | C13: assets | D13: 2452805 | E13: =D13/1024/1024 -> 2.3391771 | F13: 余念（7） | G13: 惊魂未定 | H13: 正式角色立绘 | I13: 可用于对白绑定 | J13: https://raw.githubusercontent.com/Shellingfordh/echoes-of-us/main/assets/余念（7）：惊魂未定.png
A14: assets/余念（7）：欣然愉悦.png | B14: 余念（7）：欣然愉悦.png | C14: assets | D14: 2778502 | E14: =D14/1024/1024 -> 2.649786 | F14: 余念（7） | G14: 欣然愉悦 | H14: 正式角色立绘 | I14: 可用于对白绑定 | J14: https://raw.githubusercontent.com/Shellingfordh/echoes-of-us/main/assets/余念（7）：欣然愉悦.png
A15: assets/余念（7）：正常状态.png | B15: 余念（7）：正常状态.png | C15: assets | D15: 898509 | E15: =D15/1024/1024 -> 0.85688496 | F15: 余念（7） | G15: 正常状态 | H15: 正式角色立绘 | I15: 可用于对白绑定 | J15: https://raw.githubusercontent.com/Shellingfordh/echoes-of-us/main/assets/余念（7）：正常状态.png
A16: assets/余念（7）：淡然自若.png | B16: 余念（7）：淡然自若.png | C16: assets | D16: 2467114 | E16: =D16/1024/1024 -> 2.3528233 | F16: 余念（7） | G16: 淡然自若 | H16: 正式角色立绘 | I16: 可用于对白绑定 | J16: https://raw.githubusercontent.com/Shellingfordh/echoes-of-us/main/assets/余念（7）：淡然自若.png
A17: assets/余念（7）：积郁憋闷.png | B17: 余念（7）：积郁憋闷.png | C17: assets | D17: 2350770 | E17: =D17/1024/1024 -> 2.241869 | F17: 余念（7） | G17: 积郁憋闷 | H17: 正式角色立绘 | I17: 可用于对白绑定 | J17: https://raw.githubusercontent.com/Shellingfordh/echoes-of-us/main/assets/余念（7）：积郁憋闷.png
... A35: assets/余秀兰（48）：阴…….jpg | B35: 余秀兰（48）：阴…….jpg | C35: assets | D35: 104764 | E35: =D35/1024/1024 -> 0.099910736 | F35: 余秀兰（48） | G35: 阴…… | H35: 正式角色立绘 | I35: 可用于对白绑定 | J35: https://raw.githubusercontent.com/Shellingfordh/echoes-of-us/main/assets/余秀兰（48）：阴…….jpg
A38: 资产与版本审计 | B38: 资产与版本审计 | C38: 资产与版本审计 | D38: 资产与版本审计 | E38: 资产与版本审计 | F38: 资产与版本审计 | G38: 资产与版本审计 | H38: 资产与版本审计 | I38: 资产与版本审计 | J38: 资产与版本审计
A39: 检查项 | B39: 仓库现状 | C39: 处理
A40: assets | B40: 30 个文件；29 个角色立绘 | C40: 已绑定 77/78 条对白
A41: 重复内容 | B41: 2 个文件与其他文件 SHA 相同 | C41: 保留文件名映射；建议后续去重
A42: 对白版本 | B42: 文档 v3.7 / 运行 JSON version 1 | C42: 本表以剧情对白表 v3.7 为准

Sheet 映射规则
A1: 立绘槽位映射规则 | B1: 立绘槽位映射规则 | C1: 立绘槽位映射规则 | D1: 立绘槽位映射规则 | E1: 立绘槽位映射规则 | F1: 立绘槽位映射规则
A2: 推荐槽位不是现有文件名，而是供美术与程序统一命名的建议 ID；补齐立绘后，可在“对白匹配”表中将状态改为“已绑定”。 | B2: 推荐槽位不是现有文件名，而是供美术与程序统一命名的建议 ID；补齐立绘后，可在“对白匹配”表中将状态改为“已绑定”。 | C2: 推荐槽位不是现有文件名，而是供美术与程序统一命名的建议 ID；补齐立绘后，可在“对白匹配”表中将状态改为“已绑定”。 | D2: 推荐槽位不是现有文件名，而是供美术与程序统一命名的建议 ID；补齐立绘后，可在“对白匹配”表中将状态改为“已绑定”。 | E2: 推荐槽位不是现有文件名，而是供美术与程序统一命名的建议 ID；补齐立绘后，可在“对白匹配”表中将状态改为“已绑定”。 | F2: 推荐槽位不是现有文件名，而是供美术与程序统一命名的建议 ID；补齐立绘后，可在“对白匹配”表中将状态改为“已绑定”。
A4: 角色版本规则 | B4: 角色版本规则 | C4: 角色版本规则 | D4: 角色版本规则 | E4: 角色版本规则 | F4: 角色版本规则
A5: 对白角色 | B5: 角色版本 | C5: 槽位前缀
A6: 余念／余念·独白 | B6: 余念（23岁） | C6: YN23
A7: 七岁余念 | B7: 余念（7岁） | C7: YN07
A8: 余秀兰 | B8: 余秀兰（48岁） | C8: YXL48
A9: 年轻余秀兰 | B9: 余秀兰（33岁） | C9: YXL33
A10: 高中姑娘 | B10: 高中姑娘 | C10: HS_GIRL
A12: 情绪归类规则（按优先级） | B12: 情绪归类规则（按优先级） | C12: 情绪归类规则（按优先级） | D12: 情绪归类规则（按优先级） | E12: 情绪归类规则（按优先级） | F12: 情绪归类规则（按优先级）
A13: 槽位后缀 | B13: 情绪组 | C13: 关键词示例 | D13: 说明
A14: SHOCK | B14: 震惊/警觉 | C14: 震惊、错愕、惊讶、警惕 | D14: 高优先级
A15: FEAR | B15: 恐惧/紧张 | C15: 恐惧、惊慌、危险、紧张 | D15: 高优先级
A16: SAD | B16: 受伤/低落 | C16: 受伤、失落、委屈、不舍、愧疚、压抑 | D16: 可参考现有哀悼图，但需先确认角色
A17: IRRITATED | B17: 烦躁/防御 | C17: 烦、抗拒、防御、固执、不满 | D17: 冲突/边界感
A18: WARM | B18: 温暖/轻快 | C18: 兴奋、柔软、温柔、信任、释然、安定 | D18: 正向或缓和
A19: CONCERNED | B19: 关切/专注 | C19: 担心、关心、照料、忙碌、专注、沉着 | D19: 母亲常用
A21: 命名示例 | B21: 命名示例 | C21: 命名示例 | D21: 命名示例 | E21: 命名示例 | F21: 命名示例
A22: 对白 | B22: 推荐槽位 | C22: 含义
A23: 余念；委屈/抗拒 | B23: YN23_SAD | C23: 23 岁余念，低落表情
A24: 年轻余秀兰；恐惧/镇定 | B24: YXL33_FEAR | C24: 33 岁余秀兰，紧张表情
A25: 七岁余念；兴奋 | B25: YN07_WARM | C25: 7 岁余念，轻快表情
